<!-- DO NOT EDIT: Generated from iris.sdf.jinja -->
<sdf version='1.6'>
  <model name='iris'>
    <link name='base_link'>
      <pose>0 0 0 0 0 0</pose>
      <inertial>
        <pose>0 0 0 0 0 0</pose>
        <mass>2.0</mass>
        <inertia>
          <ixx>0.029125</ixx>
          <ixy>0</ixy>
          <ixz>0</ixz>
          <iyy>0.029125</iyy>
          <iyz>0</iyz>
          <izz>0.055225</izz>

          <!-- <ixx>0.50781</ixx>
          <ixy>0</ixy>
          <ixz>0</ixz>
          <iyy>0.50781</iyy>
          <iyz>0</iyz>
          <izz>0.72975</izz> -->
        </inertia>
      </inertial>
      <collision name='base_link_inertia_collision'>
        <pose>0 0 0 0 0 0</pose>
        <geometry>
          <box>
            <size>0.47 0.47 0.11</size>
          </box>
        </geometry>
        <surface>
          <contact>
            <ode>
              <min_depth>0.001</min_depth>
              <max_vel>0</max_vel>
            </ode>
          </contact>
          <friction>
            <ode/>
          </friction>
        </surface>
      </collision>
      <visual name='base_link_inertia_visual'>
        <pose>0 0 0 0 0 0</pose>
        <geometry>
          <mesh>
            <scale>1 1 1</scale>
            <uri>model://iris/meshes/iris.stl</uri>
          </mesh>
        </geometry>
        <material>
          <script>
            <name>Gazebo/DarkGrey</name>
            <uri>file://media/materials/scripts/gazebo.material</uri>
          </script>
        </material>
      </visual>
      <gravity>1</gravity>
      <velocity_decay/>
    </link>
    <link name='/imu_link'>
      <pose>0 0 0 0 0 0</pose>
      <inertial>
        <pose>0 0 0 0 0 0</pose>
        <mass>0.015</mass>
        <inertia>
          <ixx>1e-05</ixx>
          <ixy>0</ixy>
          <ixz>0</ixz>
          <iyy>1e-05</iyy>
          <iyz>0</iyz>
          <izz>1e-05</izz>
        </inertia>
      </inertial>
    </link>
    <joint name='/imu_joint' type='revolute'>
      <child>/imu_link</child>
      <parent>base_link</parent>
      <axis>
        <xyz>1 0 0</xyz>
        <limit>
          <lower>0</lower>
          <upper>0</upper>
          <effort>0</effort>
          <velocity>0</velocity>
        </limit>
        <dynamics>
          <spring_reference>0</spring_reference>
          <spring_stiffness>0</spring_stiffness>
        </dynamics>
        <use_parent_model_frame>1</use_parent_model_frame>
      </axis>
    </joint>
    <link name='rotor_0'>
      <pose>0.13 -0.22 0.023 0 0 0</pose>
      <inertial>
        <pose>0 0 0 0 0 0</pose>
        <mass>0.05</mass>
        <inertia>
          <ixx>9.75e-07</ixx>
          <ixy>0</ixy>
          <ixz>0</ixz>
          <iyy>0.000273104</iyy>
          <iyz>0</iyz>
          <izz>0.000274004</izz>
        </inertia>
      </inertial>
      <collision name='rotor_0_collision'>
        <pose>0 0 0 0 0 0</pose>
        <geometry>
          <cylinder>
            <length>0.005</length>
            <radius>0.128</radius>
          </cylinder>
        </geometry>
        <surface>
          <contact>
            <ode/>
          </contact>
          <friction>
            <ode/>
          </friction>
        </surface>
      </collision>
      <visual name='rotor_0_visual'>
        <pose>0 0 0 0 0 0</pose>
        <geometry>
          <mesh>
            <scale>1 1 1</scale>
            <uri>model://iris/meshes/iris_prop_ccw.dae</uri>
          </mesh>
        </geometry>
        <material>
          <script>
            <name>Gazebo/Blue</name>
            <uri>file://media/materials/scripts/gazebo.material</uri>
          </script>
        </material>
      </visual>
      <gravity>1</gravity>
      <velocity_decay/>
    </link>
    <joint name='rotor_0_joint' type='revolute'>
      <child>rotor_0</child>
      <parent>base_link</parent>
      <axis>
        <xyz>0 0 1</xyz>
        <limit>
          <lower>-1e+16</lower>
          <upper>1e+16</upper>
        </limit>
        <dynamics>
          <spring_reference>0</spring_reference>
          <spring_stiffness>0</spring_stiffness>
        </dynamics>
        <use_parent_model_frame>1</use_parent_model_frame>
      </axis>
    </joint>
    <link name='rotor_1'>
      <pose>-0.13 0.2 0.023 0 0 0</pose>
      <inertial>
        <pose>0 0 0 0 0 0</pose>
        <mass>0.05</mass>
        <inertia>
          <ixx>9.75e-07</ixx>
          <ixy>0</ixy>
          <ixz>0</ixz>
          <iyy>0.000273104</iyy>
          <iyz>0</iyz>
          <izz>0.000274004</izz>
        </inertia>
      </inertial>
      <collision name='rotor_1_collision'>
        <pose>0 0 0 0 0 0</pose>
        <geometry>
          <cylinder>
            <length>0.005</length>
            <radius>0.128</radius>
          </cylinder>
        </geometry>
        <surface>
          <contact>
            <ode/>
          </contact>
          <friction>
            <ode/>
          </friction>
        </surface>
      </collision>
      <visual name='rotor_1_visual'>
        <pose>0 0 0 0 0 0</pose>
        <geometry>
          <mesh>
            <scale>1 1 1</scale>
            <uri>model://iris/meshes/iris_prop_ccw.dae</uri>
          </mesh>
        </geometry>
        <material>
          <script>
            <name>Gazebo/White</name>
            <uri>file://media/materials/scripts/gazebo.material</uri>
          </script>
        </material>
      </visual>
      <gravity>1</gravity>
      <velocity_decay/>
    </link>
    <joint name='rotor_1_joint' type='revolute'>
      <child>rotor_1</child>
      <parent>base_link</parent>
      <axis>
        <xyz>0 0 1</xyz>
        <limit>
          <lower>-1e+16</lower>
          <upper>1e+16</upper>
        </limit>
        <dynamics>
          <spring_reference>0</spring_reference>
          <spring_stiffness>0</spring_stiffness>
        </dynamics>
        <use_parent_model_frame>1</use_parent_model_frame>
      </axis>
    </joint>
    <link name='rotor_2'>
      <pose>0.13 0.22 0.023 0 0 0</pose>
      <inertial>
        <pose>0 0 0 0 0 0</pose>
        <mass>0.05</mass>
        <inertia>
          <ixx>9.75e-07</ixx>
          <ixy>0</ixy>
          <ixz>0</ixz>
          <iyy>0.000273104</iyy>
          <iyz>0</iyz>
          <izz>0.000274004</izz>
        </inertia>
      </inertial>
      <collision name='rotor_2_collision'>
        <pose>0 0 0 0 0 0</pose>
        <geometry>
          <cylinder>
            <!-- <length>0.005</length> --> 
            <length>0.005</length>
            <radius>0.128</radius>
          </cylinder>
        </geometry>
        <surface>
          <contact>
            <ode/>
          </contact>
          <friction>
            <ode/>
          </friction>
        </surface>
      </collision>
      <visual name='rotor_2_visual'>
        <pose>0 0 0 0 0 0</pose>
        <geometry>
          <mesh>
            <scale>1 1 1</scale>
            <uri>model://iris/meshes/iris_prop_cw.dae</uri>
          </mesh>
        </geometry>
        <material>
          <script>
            <name>Gazebo/Blue</name>
            <uri>file://media/materials/scripts/gazebo.material</uri>
          </script>
        </material>
      </visual>
      <gravity>1</gravity>
      <velocity_decay/>
    </link>
    <joint name='rotor_2_joint' type='revolute'>
      <child>rotor_2</child>
      <parent>base_link</parent>
      <axis>
        <xyz>0 0 1</xyz>
        <limit>
          <lower>-1e+16</lower>
          <upper>1e+16</upper>
        </limit>
        <dynamics>
          <spring_reference>0</spring_reference>
          <spring_stiffness>0</spring_stiffness>
        </dynamics>
        <use_parent_model_frame>1</use_parent_model_frame>
      </axis>
    </joint>
    <link name='rotor_3'>
      <pose>-0.13 -0.2 0.023 0 0 0</pose>
      <inertial>
        <pose>0 0 0 0 0 0</pose>
        <mass>0.05</mass>
        <inertia>
          <ixx>9.75e-07</ixx>
          <ixy>0</ixy>
          <ixz>0</ixz>
          <iyy>0.000273104</iyy>
          <iyz>0</iyz>
          <izz>0.000274004</izz>
        </inertia>
      </inertial>
      <collision name='rotor_3_collision'>
        <pose>0 0 0 0 0 0</pose>
        <geometry>
          <cylinder>
            <length>0.005</length>
            <radius>0.128</radius>
          </cylinder>
        </geometry>
        <surface>
          <contact>
            <ode/>
          </contact>
          <friction>
            <ode/>
          </friction>
        </surface>
      </collision>
      <visual name='rotor_3_visual'>
        <pose>0 0 0 0 0 0</pose>
        <geometry>
          <mesh>
            <scale>1 1 1</scale>
            <uri>model://iris/meshes/iris_prop_cw.dae</uri>
          </mesh>
        </geometry>
        <material>
          <script>
            <name>Gazebo/White</name>
            <uri>file://media/materials/scripts/gazebo.material</uri>
          </script>
        </material>
      </visual>
      <gravity>1</gravity>
      <velocity_decay/>
    </link>
    <joint name='rotor_3_joint' type='revolute'>
      <child>rotor_3</child>
      <parent>base_link</parent>
      <axis>
        <xyz>0 0 1</xyz>
        <limit>
          <lower>-1e+16</lower>
          <upper>1e+16</upper>
        </limit>
        <dynamics>
          <spring_reference>0</spring_reference>
          <spring_stiffness>0</spring_stiffness>
        </dynamics>
        <use_parent_model_frame>1</use_parent_model_frame>
      </axis>
    </joint>


    <!-- PRISMATIC LEG 1 (rear right)-->
    <link name='thigh_01'>
      <!-- <pose>-0.07 -0.03 0.06 0 0 0</pose> -->
      <pose>-0.275 -0.265 0.045 0 0 0</pose>
      <inertial>
        <pose>0 0 0 0 0 0</pose>
        <mass>0.05</mass>
        <inertia>
          <ixx>0.0166667</ixx>
          <ixy>0</ixy>
          <ixz>0</ixz>
          <iyy>0.0166667</iyy>
          <iyz>0</iyz>
          <izz>0.0166667</izz>
        </inertia>
      </inertial>
      <collision name='thigh_01_collision'>
        <pose>0 0 0 0 0 0</pose>
        <geometry>
          <box>
            <size>0.02 0.02 0.075</size>
          </box>
        </geometry>
        <surface>
          <contact>
            <ode/>
          </contact>
          <friction>
            <ode/>
          </friction>
        </surface>
      </collision>
      <visual name='thigh_01_visual'>
        <pose>0 0 0 0 0 0</pose>
        <geometry>
          <box>
            <size>0.02 0.02 0.075</size>
          </box>
        </geometry>
        <material>
          <script>
            <name>Gazebo/Green</name>
            <uri>file://media/materials/scripts/gazebo.material</uri>
          </script>
        </material>
      </visual>
      <gravity>1</gravity>
      <velocity_decay/>
    </link>
    <joint name='thigh_01_joint' type='fixed'>
      <child>thigh_01</child>
      <parent>base_link</parent>
      <pose>0.0 0.0 0.025 0 0 0</pose>
      <axis>
        <!-- Change this to allow the actuation in the respective axis -->
        <xyz>0 0 0</xyz>
        <limit>
          <lower>0</lower>
          <upper>0</upper>
          <effort>0</effort>
          <velocity>0.0</velocity>
        </limit>
        <dynamics>
          <damping>1</damping>
        </dynamics>
        <use_parent_model_frame>1</use_parent_model_frame>
      </axis>
      <physics>
        <ode>
          <implicit_spring_damper>1</implicit_spring_damper>
          <limit>
            <!-- <cfm>0.1</cfm> -->
            <cfm>0.0</cfm>
            <erp>0.2</erp>
          </limit>
        </ode>
      </physics>
    </joint>

    <link name='shin_01'>
      <!-- <pose>-0.07 -0.03 0.1 0 0 0</pose> -->
      <pose>-0.275 -0.265 0.1 0 0 0</pose>
      <inertial>
        <pose>0 0 0 0 0 0</pose>
        <mass>0.05</mass>
        <inertia>
          <ixx>0.0166667</ixx>
          <ixy>0</ixy>
          <ixz>0</ixz>
          <iyy>0.0166667</iyy>
          <iyz>0</iyz>
          <izz>0.0166667</izz>
        </inertia>
      </inertial>
      <collision name='shin_01_collision'>
        <pose>0 0 0 0 0 0</pose>
        <geometry>
          <box>
            <size>0.01 0.01 0.045</size>
          </box>
        </geometry>
        <surface>
          <contact>
            <ode>
              <kp>1000000.0</kp>
              <kd>100.0</kd>
              <max_vel>1.0</max_vel>
              <min_depth>0.002</min_depth>
            </ode>
          </contact>
          <friction>
            <ode>
              <mu>0.475</mu>
              <mu2>0.475</mu2>
            </ode>
          </friction>
        </surface>
      </collision>
      <visual name='shin_01_visual'>
        <pose>0 0 0 0 0 0</pose>
        <geometry>
          <box>
            <size>0.01 0.01 0.045</size>
          </box>
        </geometry>
        <material>
          <script>
            <name>Gazebo/Grey</name>
            <uri>file://media/materials/scripts/gazebo.material</uri>
          </script>
        </material>
      </visual>
      <gravity>1</gravity>
      <velocity_decay/>
    </link>
    <joint name='shin_01_joint' type='prismatic'>
      <child>shin_01</child>
      <parent>thigh_01</parent>
      <pose>0.0 0.0 0.025 0 0 0</pose>
      <axis>
        <xyz>0 0 1</xyz>
        <limit>
          <lower>0</lower>
          <upper>1</upper>
          <effort>1000</effort>
          <velocity>0.5</velocity>
        </limit>
        <dynamics>
          <!-- <spring_stiffness>111.11</spring_stiffness>
          <spring_reference>0.0</spring_reference>
          <damping>0</damping> -->
          <!-- <spring_stiffness>2500</spring_stiffness> -->
          <spring_stiffness>322</spring_stiffness>
          <spring_reference>0.0</spring_reference>
          <damping>20.0</damping>
          <friction>0.475</friction> -->
        </dynamics>
        <!-- <use_parent_model_frame>1</use_parent_model_frame> -->
        <use_parent_model_frame>0</use_parent_model_frame>
      </axis>
      <physics>
        <ode>
          <implicit_spring_damper>1</implicit_spring_damper>
          <cfm_damping>1</cfm_damping>
          <limit>
            <cfm>0.1</cfm>
            <!-- <cfm>0</cfm> -->
            <erp>0.2</erp>
          </limit>
        </ode>
      </physics>
    </joint>



    <!-- PRISMATIC LEG 2 (rear left)-->
    <link name='thigh_02'>
      <!-- <pose>-0.07 0.03 0.06 0 0 0</pose> -->
      <pose>-0.275 0.265 0.045 0 0 0</pose>
      <inertial>
        <pose>0 0 0 0 0 0</pose>
        <mass>0.05</mass>
        <inertia>
          <ixx>0.0166667</ixx>
          <ixy>0</ixy>
          <ixz>0</ixz>
          <iyy>0.0166667</iyy>
          <iyz>0</iyz>
          <izz>0.0166667</izz>
        </inertia>
      </inertial>
      <collision name='thigh_02_collision'>
        <pose>0 0 0 0 0 0</pose>
        <geometry>
          <box>
            <size>0.02 0.02 0.075</size>
          </box>
        </geometry>
        <surface>
          <contact>
            <ode/>
          </contact>
          <friction>
            <ode/>
          </friction>
        </surface>
      </collision>
      <visual name='thigh_02_visual'>
        <pose>0 0 0 0 0 0</pose>
        <geometry>
          <box>
            <size>0.02 0.02 0.075</size>
          </box>
        </geometry>
        <material>
          <script>
            <name>Gazebo/Green</name>
            <uri>file://media/materials/scripts/gazebo.material</uri>
          </script>
        </material>
      </visual>
      <gravity>1</gravity>
      <velocity_decay/>
    </link>
    <joint name='thigh_02_joint' type='fixed'>
      <child>thigh_02</child>
      <parent>base_link</parent>
      <pose>0.0 0.0 0.025 0 0 0</pose>
      <axis>
        <!-- Change this to allow the actuation in the respective axis -->
        <xyz>0 0 0</xyz>
        <limit>
          <lower>0</lower>
          <upper>3</upper>
          <effort>100</effort>
          <velocity>0.2</velocity>
        </limit>
        <dynamics>
          <damping>1</damping>
        </dynamics>
        <use_parent_model_frame>1</use_parent_model_frame>
      </axis>
      <physics>
        <ode>
          <implicit_spring_damper>1</implicit_spring_damper>
          <limit>
            <!-- <cfm>0.1</cfm> -->
            <cfm>0.0</cfm>
            <erp>0.2</erp>
          </limit>
        </ode>
      </physics>
    </joint>

    <link name='shin_02'>
      <!-- <pose>-0.07 0.03 0.1 0 0 0</pose> -->
      <pose>-0.275 0.265 0.1 0 0 0</pose>
      <inertial>
        <pose>0 0 0 0 0 0</pose>
        <mass>0.05</mass>
        <inertia>
          <ixx>0.0166667</ixx>
          <ixy>0</ixy>
          <ixz>0</ixz>
          <iyy>0.0166667</iyy>
          <iyz>0</iyz>
          <izz>0.0166667</izz>
        </inertia>
      </inertial>
      <collision name='shin_02_collision'>
        <pose>0 0 0 0 0 0</pose>
        <geometry>
          <box>
            <size>0.01 0.01 0.045</size>
          </box>
        </geometry>
        <surface>
          <contact>
            <ode>
              <kp>1000000.0</kp>
              <kd>100.0</kd>
              <max_vel>1.0</max_vel>
              <min_depth>0.002</min_depth>
            </ode>
          </contact>
          <friction>
            <ode>
              <mu>0.475</mu>
              <mu2>0.475</mu2>
            </ode>
          </friction>
        </surface>
      </collision>
      <visual name='shin_02_visual'>
        <pose>0 0 0 0 0 0</pose>
        <geometry>
          <box>
            <size>0.01 0.01 0.045</size>
          </box>
        </geometry>
        <material>
          <script>
            <name>Gazebo/Grey</name>
            <uri>file://media/materials/scripts/gazebo.material</uri>
          </script>
        </material>
      </visual>
      <gravity>1</gravity>
      <velocity_decay/>
    </link>
    <joint name='shin_02_joint' type='prismatic'>
      <child>shin_02</child>
      <parent>thigh_02</parent>
      <pose>0.0 0.0 0.025 0 0 0</pose>
      <axis>
        <xyz>0 0 1</xyz>
        <limit>
          <lower>0</lower>
          <upper>100</upper>
          <effort>1000</effort>
          <velocity>0.5</velocity>
        </limit>
        <dynamics>
          <!-- <spring_stiffness>111.11</spring_stiffness>
          <spring_reference>0.0</spring_reference>
          <damping>0</damping> -->
          <spring_stiffness>322</spring_stiffness>
          <spring_reference>0.0</spring_reference>
          <damping>20.0</damping>
          <friction>0.475</friction>
        </dynamics>
        <!-- <use_parent_model_frame>1</use_parent_model_frame> -->
        <use_parent_model_frame>0</use_parent_model_frame>
      </axis>
      <physics>
        <ode>
          <implicit_spring_damper>1</implicit_spring_damper>
          <cfm_damping>1</cfm_damping>
          <limit>
            <!-- <cfm>0.1</cfm> -->
            <cfm>0.1</cfm>
            <erp>0.2</erp>
          </limit>
        </ode>
      </physics>
    </joint>



    <!-- PRISMATIC LEG 3 (front right)-->
    <link name='thigh_03'>
      <!-- <pose>0.07 -0.03 0.06 0 0 0</pose> -->
      <pose>0.265 -0.275 0.045 0 0 0</pose>
      <inertial>
        <pose>0 0 0 0 0 0</pose>
        <mass>0.05</mass>
        <inertia>
          <ixx>0.0166667</ixx>
          <ixy>0</ixy>
          <ixz>0</ixz>
          <iyy>0.0166667</iyy>
          <iyz>0</iyz>
          <izz>0.0166667</izz>
        </inertia>
      </inertial>
      <collision name='thigh_03_collision'>
        <pose>0 0 0 0 0 0</pose>
        <geometry>
          <box>
            <size>0.02 0.02 0.075</size>
          </box>
        </geometry>
        <surface>
          <contact>
            <ode/>
          </contact>
          <friction>
            <ode/>
          </friction>
        </surface>
      </collision>
      <visual name='thigh_03_visual'>
        <pose>0 0 0 0 0 0</pose>
        <geometry>
          <box>
            <size>0.02 0.02 0.075</size>
          </box>
        </geometry>
        <material>
          <script>
            <name>Gazebo/Blue</name>
            <uri>file://media/materials/scripts/gazebo.material</uri>
          </script>
        </material>
      </visual>
      <gravity>1</gravity>
      <velocity_decay/>
    </link>
    <joint name='thigh_03_joint' type='fixed'>
      <child>thigh_03</child>
      <parent>base_link</parent>
      <pose>0.0 0.0 0.025 0 0 0</pose>
      <axis>
        <!-- Change this to allow the actuation in the respective axis -->
        <xyz>0 0 0</xyz>
        <limit>
          <lower>0</lower>
          <upper>3</upper>
          <effort>100</effort>
          <velocity>0.2</velocity>
        </limit>
        <dynamics>
          <damping>1</damping>
        </dynamics>
        <use_parent_model_frame>1</use_parent_model_frame>
      </axis>
      <physics>
        <ode>
          <implicit_spring_damper>1</implicit_spring_damper>
          <limit>
            <!-- <cfm>0.1</cfm> -->
            <cfm>0.0</cfm>
            <erp>0.2</erp>
          </limit>
        </ode>
      </physics>
    </joint>

      <link name='shin_03'>
      <!-- <pose>0.07 -0.03 0.1 0 0 0</pose> -->
      <pose>0.265 -0.275 0.1 0 0 0</pose>
      <inertial>
        <pose>0 0 0 0 0 0</pose>
        <mass>0.05</mass>
        <inertia>
          <ixx>0.0166667</ixx>
          <ixy>0</ixy>
          <ixz>0</ixz>
          <iyy>0.0166667</iyy>
          <iyz>0</iyz>
          <izz>0.0166667</izz>
        </inertia>
      </inertial>
      <collision name='shin_03_collision'>
        <pose>0 0 0 0 0 0</pose>
        <geometry>
          <box>
            <size>0.01 0.01 0.045</size>
          </box>
        </geometry>
        <surface>
          <contact>
            <ode>
              <kp>1000000.0</kp>
              <kd>100.0</kd>
              <max_vel>1.0</max_vel>
              <min_depth>0.002</min_depth>
            </ode>
          </contact>
          <friction>
            <ode>
              <mu>0.475</mu>
              <mu2>0.475</mu2>
            </ode>
          </friction>
        </surface>
      </collision>
      <visual name='shin_03_visual'>
        <pose>0 0 0 0 0 0</pose>
        <geometry>
          <box>
            <size>0.01 0.01 0.045</size>
          </box>
        </geometry>
        <material>
          <script>
            <name>Gazebo/Grey</name>
            <uri>file://media/materials/scripts/gazebo.material</uri>
          </script>
        </material>
      </visual>
      <gravity>1</gravity>
      <velocity_decay/>
    </link>
    <joint name='shin_03_joint' type='prismatic'>
      <child>shin_03</child>
      <parent>thigh_03</parent>
      <pose>0.0 0.0 0.025 0 0 0</pose>
      <axis>
        <xyz>0 0 1</xyz>
        <limit>
          <lower>0</lower>
          <upper>100</upper>
          <effort>1000</effort>
          <velocity>0.5</velocity>
        </limit>
        <dynamics>
          <!-- <spring_stiffness>111.11</spring_stiffness>
          <spring_reference>0.0</spring_reference>
          <damping>0</damping> -->
          <spring_stiffness>322</spring_stiffness>
          <spring_reference>0.0</spring_reference>
          <damping>20.0</damping>
          <friction>0.475</friction>
        </dynamics>
        <!-- <use_parent_model_frame>1</use_parent_model_frame> -->
        <use_parent_model_frame>0</use_parent_model_frame>
      </axis>
      <physics>
        <ode>
          <implicit_spring_damper>1</implicit_spring_damper>
          <cfm_damping>1</cfm_damping>
          <limit>
            <!-- <cfm>0.1</cfm> -->
            <cfm>0.1</cfm>
            <erp>0.2</erp>
          </limit>
        </ode>
      </physics>
    </joint>



    <!-- PRISMATIC LEG 4 (front left)-->
    <link name='thigh_04'>
      <!-- <pose>0.07 0.03 0.06 0 0 0</pose> -->
      <pose>0.265 0.275 0.045 0 0 0</pose>
      <inertial>
        <pose>0 0 0 0 0 0</pose>
        <mass>0.05</mass>
        <inertia>
          <ixx>0.0166667</ixx>
          <ixy>0</ixy>
          <ixz>0</ixz>
          <iyy>0.0166667</iyy>
          <iyz>0</iyz>
          <izz>0.0166667</izz>
        </inertia>
      </inertial>
      <collision name='thigh_04_collision'>
        <pose>0 0 0 0 0 0</pose>
        <geometry>
          <box>
            <size>0.02 0.02 0.075</size>
          </box>
        </geometry>
        <surface>
          <contact>
            <ode/>
          </contact>
          <friction>
            <ode/>
          </friction>
        </surface>
      </collision>
      <visual name='thigh_04_visual'>
        <pose>0 0 0 0 0 0</pose>
        <geometry>
          <box>
            <size>0.02 0.02 0.075</size>
          </box>
        </geometry>
        <material>
          <script>
            <name>Gazebo/Blue</name>
            <uri>file://media/materials/scripts/gazebo.material</uri>
          </script>
        </material>
      </visual>
      <gravity>1</gravity>
      <velocity_decay/>
    </link>
    <joint name='thigh_04_joint' type='fixed'>
      <child>thigh_04</child>
      <parent>base_link</parent>
      <pose>0.0 0.0 0.025 0 0 0</pose>
      <axis>
        <!-- Change this to allow the actuation in the respective axis -->
        <xyz>0 0 0</xyz>
        <limit>
          <lower>0</lower>
          <upper>3</upper>
          <effort>100</effort>
          <velocity>0.2</velocity>
        </limit>
        <dynamics>
          <damping>1</damping>
        </dynamics>
        <use_parent_model_frame>1</use_parent_model_frame>
      </axis>
      <physics>
        <ode>
          <implicit_spring_damper>1</implicit_spring_damper>
          <limit>
            <!-- <cfm>0.1</cfm> -->
            <cfm>0.0</cfm>
            <erp>0.2</erp>
          </limit>
        </ode>
      </physics>
    </joint>

    <link name='shin_04'>
      <!-- <pose>0.07 0.03 0.1 0 0 0</pose> -->
      <pose>0.265 0.275 0.1 0 0 0</pose>
      <inertial>
        <pose>0 0 0 0 0 0</pose>
        <mass>0.05</mass>
        <inertia>
          <ixx>0.0166667</ixx>
          <ixy>0</ixy>
          <ixz>0</ixz>
          <iyy>0.0166667</iyy>
          <iyz>0</iyz>
          <izz>0.0166667</izz>
        </inertia>
      </inertial>
      <collision name='shin_04_collision'>
        <pose>0 0 0 0 0 0</pose>
        <geometry>
          <box>
            <size>0.01 0.01 0.045</size>
          </box>
        </geometry>
        <surface>
          <contact>
            <ode>
              <kp>1000000.0</kp>
              <kd>100.0</kd>
              <max_vel>1.0</max_vel>
              <min_depth>0.002</min_depth>
            </ode>
          </contact>
          <friction>
            <ode>
              <mu>0.475</mu>
              <mu2>0.475</mu2>
            </ode>
          </friction>
        </surface>
      </collision>
      <visual name='shin_04_visual'>
        <pose>0 0 0 0 0 0</pose>
        <geometry>
          <box>
            <size>0.01 0.01 0.045</size>
          </box>
        </geometry>
        <material>
          <script>
            <name>Gazebo/Grey</name>
            <uri>file://media/materials/scripts/gazebo.material</uri>
          </script>
        </material>
      </visual>
      <gravity>1</gravity>
      <velocity_decay/>
    </link>
    <joint name='shin_04_joint' type='prismatic'>
      <child>shin_04</child>
      <parent>thigh_04</parent>
      <!-- <pose>0.0 0.0 0.025 0 0 0</pose> -->
      <pose>0.0 0.0 0.025 0 0 0</pose>
      <axis>
        <xyz>0 0 1</xyz>
        <limit>
          <lower>0</lower>
          <upper>100</upper>
          <effort>1000</effort>
          <velocity>0.5</velocity>
        </limit>
        <dynamics>
          <!-- <spring_stiffness>111.11</spring_stiffness>
          <spring_reference>0.0</spring_reference>
          <damping>0</damping> -->
          <spring_stiffness>322</spring_stiffness>
          <spring_reference>0.0</spring_reference>
          <damping>20.0</damping>
          <friction>0.475</friction>
        </dynamics>
        <!-- <use_parent_model_frame>1</use_parent_model_frame> -->
        <use_parent_model_frame>0</use_parent_model_frame>
      </axis>
      <physics>
        <ode>
          <implicit_spring_damper>1</implicit_spring_damper>
          <cfm_damping>1</cfm_damping>
          <limit>
            <!-- <cfm>0.1</cfm> -->
            <cfm>0.1</cfm>
            <erp>0.2</erp>
          </limit>
        </ode>
      </physics>
    </joint>
    
    
    <!-- PRISMATIC LEG 5 (front left)-->
    <link name='thigh_05'>
      <!-- <pose>0.07 0.03 0.06 0 0 0</pose> -->
      <pose>0.0 0.0 0.07 0 0 0</pose>
      <inertial>
        <pose>0 0 0 0 0 0</pose>
        <mass>0.05</mass>
        <inertia>
          <ixx>0.0166667</ixx>
          <ixy>0</ixy>
          <ixz>0</ixz>
          <iyy>0.0166667</iyy>
          <iyz>0</iyz>
          <izz>0.0166667</izz>
        </inertia>
      </inertial>
      <collision name='thigh_05_collision'>
        <pose>0 0 0 0 0 0</pose>
        <geometry>
          <box>
            <size>0.02 0.02 0.045</size>
          </box>
        </geometry>
        <surface>
          <contact>
            <ode/>
          </contact>
          <friction>
            <ode/>
          </friction>
        </surface>
      </collision>
      <visual name='thigh_05_visual'>
        <pose>0 0 0 0 0 0</pose>
        <geometry>
          <box>
            <size>0.02 0.02 0.045</size>
          </box>
        </geometry>
        <material>
          <script>
            <name>Gazebo/Red</name>
            <uri>file://media/materials/scripts/gazebo.material</uri>
          </script>
        </material>
      </visual>
      <gravity>1</gravity>
      <velocity_decay/>
    </link>
    <joint name='thigh_05_joint' type='fixed'>
      <child>thigh_05</child>
      <parent>base_link</parent>
      <pose>0.0 0.0 0.025 0 0 0</pose>
      <axis>
        <!-- Change this to allow the actuation in the respective axis -->
        <xyz>0 0 0</xyz>
        <limit>
          <lower>0</lower>
          <upper>3</upper>
          <effort>100</effort>
          <velocity>0.2</velocity>
        </limit>
        <dynamics>
          <damping>1</damping>
        </dynamics>
        <use_parent_model_frame>1</use_parent_model_frame>
      </axis>
      <physics>
        <ode>
          <implicit_spring_damper>1</implicit_spring_damper>
          <limit>
            <!-- <cfm>0.1</cfm> -->
            <cfm>0.0</cfm>
            <erp>0.2</erp>
          </limit>
        </ode>
      </physics>
    </joint>

    <link name='shin_05'>
      <!-- <pose>0.07 0.03 0.1 0 0 0</pose> -->
      <pose>0.0 0.0 0.11 0 0 0</pose>
      <inertial>
        <pose>0 0 0 0 0 0</pose>
        <mass>0.05</mass>
        <inertia>
          <ixx>0.0166667</ixx>
          <ixy>0</ixy>
          <ixz>0</ixz>
          <iyy>0.0166667</iyy>
          <iyz>0</iyz>
          <izz>0.0166667</izz>
        </inertia>
      </inertial>
      <collision name='shin_05_collision'>
        <pose>0 0 0 0 0 0</pose>
        <geometry>
          <box>
            <size>0.01 0.01 0.045</size>
          </box>
        </geometry>
        <surface>
          <contact>
            <ode>
              <kp>1000000.0</kp>
              <kd>100.0</kd>
              <max_vel>1.0</max_vel>
              <min_depth>0.002</min_depth>
            </ode>
          </contact>
          <friction>
            <ode>
              <mu>0.475</mu>
              <mu2>0.475</mu2>
            </ode>
          </friction>
        </surface>
      </collision>
      <visual name='shin_05_visual'>
        <pose>0 0 0 0 0 0</pose>
        <geometry>
          <box>
            <size>0.01 0.01 0.045</size>
          </box>
        </geometry>
        <material>
          <script>
            <name>Gazebo/Grey</name>
            <uri>file://media/materials/scripts/gazebo.material</uri>
          </script>
        </material>
      </visual>
      <gravity>1</gravity>
      <velocity_decay/>
    </link>
    <joint name='shin_05_joint' type='prismatic'>
      <child>shin_05</child>
      <parent>thigh_05</parent>
      <!-- <pose>0.0 0.0 0.025 0 0 0</pose> -->
      <pose>0.0 0.0 0.025 0 0 0</pose>
      <axis>
        <xyz>0 0 1</xyz>
        <limit>
          <lower>0</lower>
          <upper>100</upper>
          <effort>1000</effort>
          <velocity>0.5</velocity>
        </limit>
        <dynamics>
          <!-- <spring_stiffness>111.11</spring_stiffness>
          <spring_reference>0.0</spring_reference>
          <damping>0</damping> -->
          <spring_stiffness>455</spring_stiffness>
          <spring_reference>0.0</spring_reference>
          <damping>20.0</damping>
          <friction>0.475</friction>
        </dynamics>
        <!-- <use_parent_model_frame>1</use_parent_model_frame> -->
        <use_parent_model_frame>0</use_parent_model_frame>
      </axis>
      <physics>
        <ode>
          <implicit_spring_damper>1</implicit_spring_damper>
          <cfm_damping>1</cfm_damping>
          <limit>
            <!-- <cfm>0.1</cfm> -->
            <cfm>0.1</cfm>
            <erp>0.2</erp>
          </limit>
        </ode>
      </physics>
    </joint>
    
    


    <!-- Front Left -->
    <link name='extension1'>
      <pose>0.2 0.25 0.00 0 0 -1.20428</pose> <!-- 68deg -->
      <inertial>
        <pose>0 0 0 0 0 0</pose>
        <mass>0.05</mass>
        <inertia>
          <ixx>0.0166667</ixx>
          <ixy>0</ixy>
          <ixz>0</ixz>
          <iyy>0.0166667</iyy>
          <iyz>0</iyz>
          <izz>0.0166667</izz>
        </inertia>
      </inertial>
      <collision name='extension1_collision'>
        <pose>0 0 0 0 0 0</pose>
        <geometry>
          <box>
            <size>0.01 0.01 0.04</size>
          </box>
        </geometry>
        <surface>
          <contact>
            <ode/>
          </contact>
          <friction>
            <ode/>
          </friction>
        </surface>
      </collision>
      <visual name='extension1_visual'>
        <pose>0 0 0 0 0 0</pose>
        <geometry>
          <box>
            <size>0.03 0.18 0.02</size>
          </box>
        </geometry>
        <material>
          <script>
            <name>Gazebo/DarkGrey</name>
            <uri>file://media/materials/scripts/gazebo.material</uri>
          </script>
        </material>
      </visual>
      <gravity>1</gravity>
      <velocity_decay/>
    </link>
    <joint name='extension1_joint' type='fixed'>
      <child>extension1</child>
      <parent>base_link</parent>
      <pose>0.0 0.0 0.025 0 0 0</pose>
      <axis>
        <!-- Change this to allow the actuation in the respective axis -->
        <xyz>0 0 0</xyz>
        <limit>
          <lower>0</lower>
          <upper>3</upper>
          <effort>100</effort>
          <velocity>0.2</velocity>
        </limit>
        <dynamics>
          <damping>1</damping>
        </dynamics>
        <use_parent_model_frame>1</use_parent_model_frame>
      </axis>
      <physics>
        <ode>
          <implicit_spring_damper>1</implicit_spring_damper>
          <limit>
            <cfm>0.1</cfm>
            <erp>0.2</erp>
          </limit>
        </ode>
      </physics>
    </joint>

    <!-- Front Right -->
    <link name='extension2'>
      <pose>0.2 -0.25 0.00 0 0 1.20428</pose> <!-- 68deg -->
      <inertial>
        <pose>0 0 0 0 0 0</pose>
        <mass>0.05</mass>
        <inertia>
          <ixx>0.0166667</ixx>
          <ixy>0</ixy>
          <ixz>0</ixz>
          <iyy>0.0166667</iyy>
          <iyz>0</iyz>
          <izz>0.0166667</izz>
        </inertia>
      </inertial>
      <collision name='extension2_collision'>
        <pose>0 0 0 0 0 0</pose>
        <geometry>
          <box>
            <size>0.01 0.01 0.04</size>
          </box>
        </geometry>
        <surface>
          <contact>
            <ode/>
          </contact>
          <friction>
            <ode/>
          </friction>
        </surface>
      </collision>
      <visual name='extension2_visual'>
        <pose>0 0 0 0 0 0</pose>
        <geometry>
          <box>
            <size>0.03 0.18 0.02</size>
          </box>
        </geometry>
        <material>
          <script>
            <name>Gazebo/DarkGrey</name>
            <uri>file://media/materials/scripts/gazebo.material</uri>
          </script>
        </material>
      </visual>
      <gravity>1</gravity>
      <velocity_decay/>
    </link>
    <joint name='extension2_joint' type='fixed'>
      <child>extension2</child>
      <parent>base_link</parent>
      <pose>0.0 0.0 0.025 0 0 0</pose>
      <axis>
        <!-- Change this to allow the actuation in the respective axis -->
        <xyz>0 0 0</xyz>
        <limit>
          <lower>0</lower>
          <upper>3</upper>
          <effort>100</effort>
          <velocity>0.2</velocity>
        </limit>
        <dynamics>
          <damping>1</damping>
        </dynamics>
        <use_parent_model_frame>1</use_parent_model_frame>
      </axis>
      <physics>
        <ode>
          <implicit_spring_damper>1</implicit_spring_damper>
          <limit>
            <cfm>0.1</cfm>
            <erp>0.2</erp>
          </limit>
        </ode>
      </physics>
    </joint>
    
   
    <!-- Bottom Left -->
    <link name='extension3'>
      <pose>-0.21 0.24 0.0 0 0 4.34587</pose> <!-- 68deg -->
      <inertial>
        <pose>0 0 0 0 0 0</pose>
        <mass>0.05</mass>
        <inertia>
          <ixx>0.0166667</ixx>
          <ixy>0</ixy>
          <ixz>0</ixz>
          <iyy>0.0166667</iyy>
          <iyz>0</iyz>
          <izz>0.0166667</izz>
        </inertia>
      </inertial>
      <collision name='extension3_collision'>
        <pose>0 0 0 0 0 0</pose>
        <geometry>
          <box>
            <size>0.01 0.01 0.04</size>
          </box>
        </geometry>
        <surface>
          <contact>
            <ode/>
          </contact>
          <friction>
            <ode/>
          </friction>
        </surface>
      </collision>
      <visual name='extension3_visual'>
        <pose>0 0 0 0 0 0</pose>
        <geometry>
          <box>
            <size>0.03 0.18 0.02</size>
          </box>
        </geometry>
        <material>
          <script>
            <name>Gazebo/DarkGrey</name>
            <uri>file://media/materials/scripts/gazebo.material</uri>
          </script>
        </material>
      </visual>
      <gravity>1</gravity>
      <velocity_decay/>
    </link>
    <joint name='extension3_joint' type='fixed'>
      <child>extension3</child>
      <parent>base_link</parent>
      <pose>0.0 0.0 0.025 0 0 0</pose>
      <axis>
        <!-- Change this to allow the actuation in the respective axis -->
        <xyz>0 0 0</xyz>
        <limit>
          <lower>0</lower>
          <upper>3</upper>
          <effort>100</effort>
          <velocity>0.2</velocity>
        </limit>
        <dynamics>
          <damping>1</damping>
        </dynamics>
        <use_parent_model_frame>1</use_parent_model_frame>
      </axis>
      <physics>
        <ode>
          <implicit_spring_damper>1</implicit_spring_damper>
          <limit>
            <cfm>0.1</cfm>
            <erp>0.2</erp>
          </limit>
        </ode>
      </physics>
    </joint>


    <!-- Bottom Right -->
    <link name='extension4'>
      <pose>-0.21 -0.24 0.0 0 0 -4.34587</pose> <!-- 68deg -->
      <inertial>
        <pose>0 0 0 0 0 0</pose>
        <mass>0.05</mass>
        <inertia>
          <ixx>0.0166667</ixx>
          <ixy>0</ixy>
          <ixz>0</ixz>
          <iyy>0.0166667</iyy>
          <iyz>0</iyz>
          <izz>0.0166667</izz>
        </inertia>
      </inertial>
      <collision name='extension4_collision'>
        <pose>0 0 0 0 0 0</pose>
        <geometry>
          <box>
            <size>0.01 0.01 0.04</size>
          </box>
        </geometry>
        <surface>
          <contact>
            <ode/>
          </contact>
          <friction>
            <ode/>
          </friction>
        </surface>
      </collision>
      <visual name='extension4_visual'>
        <pose>0 0 0 0 0 0</pose>
        <geometry>
          <box>
            <size>0.03 0.17 0.02</size>
          </box>
        </geometry>
        <material>
          <script>
            <name>Gazebo/DarkGrey</name>
            <uri>file://media/materials/scripts/gazebo.material</uri>
          </script>
        </material>
      </visual>
      <gravity>1</gravity>
      <velocity_decay/>
    </link>
    <joint name='extension4_joint' type='fixed'>
      <child>extension4</child>
      <parent>base_link</parent>
      <pose>0.0 0.0 0.025 0 0 0</pose>
      <axis>
        <!-- Change this to allow the actuation in the respective axis -->
        <xyz>0 0 0</xyz>
        <limit>
          <lower>0</lower>
          <upper>3</upper>
          <effort>100</effort>
          <velocity>0.2</velocity>
        </limit>
        <dynamics>
          <damping>1</damping>
        </dynamics>
        <use_parent_model_frame>1</use_parent_model_frame>
      </axis>
      <physics>
        <ode>
          <implicit_spring_damper>1</implicit_spring_damper>
          <limit>
            <cfm>0.1</cfm>
            <erp>0.2</erp>
          </limit>
        </ode>
      </physics>
    </joint>




    <!-- LW 20 RANGER -->
    <link name='LW20'>
      <pose>0.11 0.0 -0.02 0 0 0</pose>
      <inertial>
        <pose>0 0 0 0 0 0</pose>
        <mass>0.019</mass>
        <inertia>
          <ixx>1e-05</ixx>
          <ixy>0</ixy>
          <ixz>0</ixz>
          <iyy>1e-05</iyy>
          <iyz>0</iyz>
          <izz>1e-05</izz>
        </inertia>
      </inertial>
      <collision name='LW20_collision'>
        <pose>0 0 0 0 0 0</pose>
        <geometry>
          <cylinder>
            <length>0.005</length>
            <radius>0.128</radius>
          </cylinder>
        </geometry>
        <surface>
          <contact>
            <ode/>
          </contact>
          <friction>
            <ode/>
          </friction>
        </surface>
      </collision>
      <visual name='LW20_visual'>
        <pose>0 0 0 0 0 0</pose>
        <geometry>
          <mesh>
            <scale>1 1 1</scale>
            <uri>model://iris/meshes/New_Lightware_LW20.dae</uri>
          </mesh>
        </geometry>
        <material>
          <script>
            <name>Gazebo/Grey</name>
            <uri>file://media/materials/scripts/gazebo.material</uri>
          </script>
        </material>
      </visual>
      <gravity>1</gravity>
      
      <!-- Add a ray sensor, and give it a name -->
      <sensor type="ray" name="sensor">
        <!-- Position the ray sensor based on the specification. Also rotate
           it by 90 degrees around the X-axis so that the <horizontal> rays
           become vertical -->
        <pose>0.0 0 0.0 0 1.5708 0</pose>

        <!-- Enable visualization to see the rays in the GUI -->
        <visualize>true</visualize>

        <!-- Set the update rate of the sensor -->
        <update_rate>30</update_rate>
          <ray>
          <!-- The scan element contains the horizontal and vertical beams.
             We are leaving out the vertical beams for this tutorial. -->
          <scan>
            <!-- The horizontal beams -->
            <horizontal>
              <!-- The velodyne has 32 beams(samples) -->
              <samples>1</samples>
              <!-- Resolution is multiplied by samples to determine number of
                   simulated beams vs interpolated beams. See:
                   http://sdformat.org/spec?ver=1.6&elem=sensor#horizontal_resolution
                   -->
              <resolution>1</resolution>
              <!-- Minimum angle in radians -->
              <min_angle>-0.0</min_angle>
              <!-- Maximum angle in radians -->
              <max_angle>0.0</max_angle>
            </horizontal>
          </scan>
          <!-- Range defines characteristics of an individual beam -->
          <range>
            <!-- Minimum distance of the beam -->
            <min>0.05</min>
            <!-- Maximum distance of the beam -->
            <max>70</max>
            <!-- Linear resolution of the beam -->
            <resolution>0.02</resolution>
          </range>
          <noise>
            <!-- Use gaussian noise -->
            <type>gaussian</type>
            <mean>0.0</mean>
            <stddev>0.02</stddev>
          </noise>
        </ray>
        <plugin name="sensor_plugin" filename='/home/sml/catkin_ws/devel/lib/libgazebo_ros_laser.so'>
          <topicName>/lw20_ranger</topicName>
        </plugin>
      </sensor>
    </link>
    <joint name='LW20_joint' type='revolute'>
      <child>LW20</child>
      <parent>base_link</parent>
      <axis>
        <xyz>0 0 0</xyz>
        <limit>
          <lower>0</lower>
          <upper>0</upper>
          <effort>0</effort>
          <velocity>0</velocity>
        </limit>
        <dynamics>
          <spring_reference>0</spring_reference>
          <spring_stiffness>0</spring_stiffness>
        </dynamics>
        <use_parent_model_frame>1</use_parent_model_frame>
      </axis>
    </joint>


    <plugin name='rosbag' filename='libgazebo_multirotor_base_plugin.so'>
      <robotNamespace/>
      <linkName>base_link</linkName>
      <rotorVelocitySlowdownSim>10</rotorVelocitySlowdownSim>
    </plugin>
    <plugin name='front_right_motor_model' filename='libgazebo_motor_model.so'>
      <robotNamespace/>
      <jointName>rotor_0_joint</jointName>
      <linkName>rotor_0</linkName>
      <turningDirection>ccw</turningDirection>
      <timeConstantUp>0.0125</timeConstantUp>
      <timeConstantDown>0.025</timeConstantDown>
      <maxRotVelocity>4400</maxRotVelocity>
      <motorConstant>2.54e-05</motorConstant>
      <momentConstant>0.06</momentConstant>
      <commandSubTopic>/gazebo/command/motor_speed</commandSubTopic>
      <motorNumber>0</motorNumber>
      <rotorDragCoefficient>0.010984</rotorDragCoefficient>
      <rollingMomentCoefficient>1e-06</rollingMomentCoefficient>
      <motorSpeedPubTopic>/motor_speed/0</motorSpeedPubTopic>
      <rotorVelocitySlowdownSim>10</rotorVelocitySlowdownSim>
    </plugin>
    <plugin name='back_left_motor_model' filename='libgazebo_motor_model.so'>
      <robotNamespace/>
      <jointName>rotor_1_joint</jointName>
      <linkName>rotor_1</linkName>
      <turningDirection>ccw</turningDirection>
      <timeConstantUp>0.0125</timeConstantUp>
      <timeConstantDown>0.025</timeConstantDown>
      <maxRotVelocity>4400</maxRotVelocity>
      <motorConstant>2.54e-05</motorConstant>
      <momentConstant>0.06</momentConstant>
      <commandSubTopic>/gazebo/command/motor_speed</commandSubTopic>
      <motorNumber>1</motorNumber>
      <rotorDragCoefficient>0.010984</rotorDragCoefficient>
      <rollingMomentCoefficient>1e-06</rollingMomentCoefficient>
      <motorSpeedPubTopic>/motor_speed/1</motorSpeedPubTopic>
      <rotorVelocitySlowdownSim>10</rotorVelocitySlowdownSim>
    </plugin>
    <plugin name='front_left_motor_model' filename='libgazebo_motor_model.so'>
      <robotNamespace/>
      <jointName>rotor_2_joint</jointName>
      <linkName>rotor_2</linkName>
      <turningDirection>cw</turningDirection>
      <timeConstantUp>0.0125</timeConstantUp>
      <timeConstantDown>0.025</timeConstantDown>
      <maxRotVelocity>4400</maxRotVelocity>
      <motorConstant>2.54e-05</motorConstant>
      <momentConstant>0.06</momentConstant>
      <commandSubTopic>/gazebo/command/motor_speed</commandSubTopic>
      <motorNumber>2</motorNumber>
      <rotorDragCoefficient>0.010984</rotorDragCoefficient>
      <rollingMomentCoefficient>1e-06</rollingMomentCoefficient>
      <motorSpeedPubTopic>/motor_speed/2</motorSpeedPubTopic>
      <rotorVelocitySlowdownSim>10</rotorVelocitySlowdownSim>
    </plugin>
    <plugin name='back_right_motor_model' filename='libgazebo_motor_model.so'>
      <robotNamespace/>
      <jointName>rotor_3_joint</jointName>
      <linkName>rotor_3</linkName>
      <turningDirection>cw</turningDirection>
      <timeConstantUp>0.0125</timeConstantUp>
      <timeConstantDown>0.025</timeConstantDown>
      <maxRotVelocity>4400</maxRotVelocity>
      <motorConstant>2.54e-05</motorConstant>
      <momentConstant>0.06</momentConstant>
      <commandSubTopic>/gazebo/command/motor_speed</commandSubTopic>
      <motorNumber>3</motorNumber>
      <rotorDragCoefficient>0.010984</rotorDragCoefficient>
      <rollingMomentCoefficient>1e-06</rollingMomentCoefficient>
      <motorSpeedPubTopic>/motor_speed/3</motorSpeedPubTopic>
      <rotorVelocitySlowdownSim>10</rotorVelocitySlowdownSim>
    </plugin>
    <include>
      <uri>model://gps</uri>
      <pose>0.1 0 0 0 0 0</pose>
      <name>gps0</name>
    </include>
    <joint name='gps0_joint' type='fixed'>
      <child>gps0::link</child>
      <parent>base_link</parent>
    </joint>
    <plugin name='groundtruth_plugin' filename='libgazebo_groundtruth_plugin.so'>
      <robotNamespace/>
    </plugin>
    <plugin name='magnetometer_plugin' filename='libgazebo_magnetometer_plugin.so'>
      <robotNamespace/>
      <pubRate>100</pubRate>
      <noiseDensity>0.0004</noiseDensity>
      <randomWalk>6.4e-06</randomWalk>
      <biasCorrelationTime>600</biasCorrelationTime>
      <magTopic>/mag</magTopic>
    </plugin>
    <plugin name='barometer_plugin' filename='libgazebo_barometer_plugin.so'>
      <robotNamespace/>
      <pubRate>50</pubRate>
      <baroTopic>/baro</baroTopic>
      <baroDriftPaPerSec>0</baroDriftPaPerSec>
    </plugin>
    <plugin name='mavlink_interface' filename='libgazebo_mavlink_interface.so'>
      <robotNamespace/>
      <imuSubTopic>/imu</imuSubTopic>
      <magSubTopic>/mag</magSubTopic>
      <baroSubTopic>/baro</baroSubTopic>
      <mavlink_addr>INADDR_ANY</mavlink_addr>
      <mavlink_tcp_port>4560</mavlink_tcp_port>
      <mavlink_udp_port>14560</mavlink_udp_port>
      <serialEnabled>0</serialEnabled>
      <serialDevice>/dev/ttyACM0</serialDevice>
      <baudRate>921600</baudRate>
      <qgc_addr>INADDR_ANY</qgc_addr>
      <qgc_udp_port>14550</qgc_udp_port>
      <sdk_addr>INADDR_ANY</sdk_addr>
      <sdk_udp_port>14540</sdk_udp_port>
      <hil_mode>0</hil_mode>
      <hil_state_level>0</hil_state_level>
      <send_vision_estimation>0</send_vision_estimation>
      <send_odometry>1</send_odometry>
      <enable_lockstep>1</enable_lockstep>
      <use_tcp>1</use_tcp>
      <motorSpeedCommandPubTopic>/gazebo/command/motor_speed</motorSpeedCommandPubTopic>
      <control_channels>
        <channel name='rotor1'>
          <input_index>0</input_index>
          <input_offset>0</input_offset>
          <input_scaling>1000</input_scaling>
          <zero_position_disarmed>0</zero_position_disarmed>
          <zero_position_armed>100</zero_position_armed>
          <joint_control_type>velocity</joint_control_type>
        </channel>
        <channel name='rotor2'>
          <input_index>1</input_index>
          <input_offset>0</input_offset>
          <input_scaling>1000</input_scaling>
          <zero_position_disarmed>0</zero_position_disarmed>
          <zero_position_armed>100</zero_position_armed>
          <joint_control_type>velocity</joint_control_type>
        </channel>
        <channel name='rotor3'>
          <input_index>2</input_index>
          <input_offset>0</input_offset>
          <input_scaling>1000</input_scaling>
          <zero_position_disarmed>0</zero_position_disarmed>
          <zero_position_armed>100</zero_position_armed>
          <joint_control_type>velocity</joint_control_type>
        </channel>
        <channel name='rotor4'>
          <input_index>3</input_index>
          <input_offset>0</input_offset>
          <input_scaling>1000</input_scaling>
          <zero_position_disarmed>0</zero_position_disarmed>
          <zero_position_armed>100</zero_position_armed>
          <joint_control_type>velocity</joint_control_type>
        </channel>
        <channel name='rotor5'>
          <input_index>4</input_index>
          <input_offset>1</input_offset>
          <input_scaling>324.6</input_scaling>
          <zero_position_disarmed>0</zero_position_disarmed>
          <zero_position_armed>0</zero_position_armed>
          <joint_control_type>velocity</joint_control_type>
          <joint_control_pid>
            <p>0.1</p>
            <i>0</i>
            <d>0</d>
            <iMax>0.0</iMax>
            <iMin>0.0</iMin>
            <cmdMax>2</cmdMax>
            <cmdMin>-2</cmdMin>
          </joint_control_pid>
          <joint_name>zephyr_delta_wing::propeller_joint</joint_name>
        </channel>
        <channel name='rotor6'>
          <input_index>5</input_index>
          <input_offset>0</input_offset>
          <input_scaling>0.524</input_scaling>
          <zero_position_disarmed>0</zero_position_disarmed>
          <zero_position_armed>0</zero_position_armed>
          <joint_control_type>position</joint_control_type>
          <joint_name>zephyr_delta_wing::flap_left_joint</joint_name>
          <joint_control_pid>
            <p>10.0</p>
            <i>0</i>
            <d>0</d>
            <iMax>0</iMax>
            <iMin>0</iMin>
            <cmdMax>20</cmdMax>
            <cmdMin>-20</cmdMin>
          </joint_control_pid>
        </channel>
        <channel name='rotor7'>
          <input_index>6</input_index>
          <input_offset>0</input_offset>
          <input_scaling>0.524</input_scaling>
          <zero_position_disarmed>0</zero_position_disarmed>
          <zero_position_armed>0</zero_position_armed>
          <joint_control_type>position</joint_control_type>
          <joint_name>zephyr_delta_wing::flap_right_joint</joint_name>
          <joint_control_pid>
            <p>10.0</p>
            <i>0</i>
            <d>0</d>
            <iMax>0</iMax>
            <iMin>0</iMin>
            <cmdMax>20</cmdMax>
            <cmdMin>-20</cmdMin>
          </joint_control_pid>
        </channel>
        <channel name='rotor8'>
          <input_index>7</input_index>
          <input_offset>0</input_offset>
          <input_scaling>0.524</input_scaling>
          <zero_position_disarmed>0</zero_position_disarmed>
          <zero_position_armed>0</zero_position_armed>
          <joint_control_type>position</joint_control_type>
        </channel>
      </control_channels>
    </plugin>
    <static>0</static>
    <plugin name='rotors_gazebo_imu_plugin' filename='libgazebo_imu_plugin.so'>
      <robotNamespace/>
      <linkName>/imu_link</linkName>
      <imuTopic>/imu</imuTopic>
      <gyroscopeNoiseDensity>0.00018665</gyroscopeNoiseDensity>
      <gyroscopeRandomWalk>3.8785e-05</gyroscopeRandomWalk>
      <gyroscopeBiasCorrelationTime>1000.0</gyroscopeBiasCorrelationTime>
      <gyroscopeTurnOnBiasSigma>0.0087</gyroscopeTurnOnBiasSigma>
      <accelerometerNoiseDensity>0.00186</accelerometerNoiseDensity>
      <accelerometerRandomWalk>0.006</accelerometerRandomWalk>
      <accelerometerBiasCorrelationTime>300.0</accelerometerBiasCorrelationTime>
      <accelerometerTurnOnBiasSigma>0.196</accelerometerTurnOnBiasSigma>
    </plugin>
    <!-- <plugin name='ce_plugin' filename="home/sml/catkin_ws/devel/lib/libce_plugin.so"/> -->
    <plugin name='Force3d_plugin' filename="/home/sml/catkin_ws/devel/lib/libForce3d_plugin.so"/>
    <!-- <plugin name='jetForce3d_plugin' filename="/home/sml/catkin_ws/devel/lib/libjetForce3d_plugin.so"/> -->
    
    <!--<plugin name='lw20_plugin' filename="/home/sml/catkin_ws/devel/lib/liblw20_plugin.so">
      <robotNamespace/>
      <linkName>LW20</linkName>
    </plugin> -->
  </model>
</sdf>
